Workbook

Sheet Budget Summary
A1: ="2027 Marketing Budget: "&Inputs!$B$5
A2: =Inputs!$B$6&" · "&Inputs!$B$7&" · "&TEXT(Inputs!$B$9,"0")&" units"
A4: Headline
A5: Total 2027 marketing budget | B5: ='Monthly Plan'!$N$41
A6: Budget per unit per year | B6: =IFERROR(B5/Inputs!$B$9,0)
A7: Budget per unit per month | B7: =IFERROR(B5/Inputs!$B$9/12,0)
A8: % of gross potential rent | B8: =IFERROR(B5/(Inputs!$B$9*Inputs!$B$10*12),0) | E8: Many operators land ~1–3% of GPR
A10: Lease demand
A11: Leases expiring in 2027 | B11: ='Monthly Plan'!$N$7
A12: Renewals | B12: ='Monthly Plan'!$N$8
A13: Move-outs (expirations + early terminations) | B13: ='Monthly Plan'!$N$9+'Monthly Plan'!$N$10
A14: Implied annual turnover rate | B14: =IFERROR(B13/Inputs!$B$9,0) | E14: Move-outs ÷ total units
A15: New leases needed | B15: ='Monthly Plan'!$N$12
A16: Lead-to-lease rate | B16: =Inputs!$B$26
A17: Leads needed | B17: ='Monthly Plan'!$N$14
A18: Tours needed | B18: ='Monthly Plan'!$N$15
A20: Efficiency checks
A21: Blended cost per lead | B21: =IFERROR('Monthly Plan'!$N$25/B17,0) | E21: Channel spend ÷ leads
A22: Cost per new lease (all-in) | B22: =IFERROR(B5/B15,0) | E22: Total budget ÷ new leases
A23: Cost per lease as % of one month's rent | B23: =IFERROR(B22/Inputs!$B$10,0)
A24: Within cost-per-lease target? | B24: =IF(B23<=Inputs!$B$30,"YES","OVER TARGET")
A26: Why it pays: cost of vacancy
A27: Projected 2027 vacancy loss from turns | B27: =B13*Inputs!$B$13*Inputs!$B$10/30 | E27: Move-outs × days vacant × daily rent
A28: Value of cutting 1 vacant day per turn | B28: =B13*Inputs!$B$10/30 | E28: Use this to justify spend that speeds up leasing
A29: Value of +5 pts renewal rate | B29: =B11*0.05*(Inputs!$B$13*Inputs!$B$10/30+IFERROR(B22,0)) | E29: Avoided vacancy + avoided acquisition cost
A31: Budget by line item
A32: Line item | B32: 2027 Budget ($) | C32: 2026 Actual ($) | D32: Variance ($) | E32: Share of budget
A33: =Inputs!$A$50 | B33: ='Monthly Plan'!$N$18 | C33: =IF(Inputs!$F$50="","",Inputs!$F$50) | D33: =IF(C33="","",B33-C33) | E33: =IFERROR(B33/B5,0)
A34: =Inputs!$A$51 | B34: ='Monthly Plan'!$N$19 | C34: =IF(Inputs!$F$51="","",Inputs!$F$51) | D34: =IF(C34="","",B34-C34) | E34: =IFERROR(B34/B5,0)
A35: =Inputs!$A$52 | B35: ='Monthly Plan'!$N$20 | C35: =IF(Inputs!$F$52="","",Inputs!$F$52) | D35: =IF(C35="","",B35-C35) | E35: =IFERROR(B35/B5,0)
A36: =Inputs!$A$53 | B36: ='Monthly Plan'!$N$21 | C36: =IF(Inputs!$F$53="","",Inputs!$F$53) | D36: =IF(C36="","",B36-C36) | E36: =IFERROR(B36/B5,0)
A37: =Inputs!$A$54 | B37: ='Monthly Plan'!$N$22 | C37: =IF(Inputs!$F$54="","",Inputs!$F$54) | D37: =IF(C37="","",B37-C37) | E37: =IFERROR(B37/B5,0)
A38: =Inputs!$A$55 | B38: ='Monthly Plan'!$N$23 | C38: =IF(Inputs!$F$55="","",Inputs!$F$55) | D38: =IF(C38="","",B38-C38) | E38: =IFERROR(B38/B5,0)
A39: =Inputs!$A$56 | B39: ='Monthly Plan'!$N$24 | C39: =IF(Inputs!$F$56="","",Inputs!$F$56) | D39: =IF(C39="","",B39-C39) | E39: =IFERROR(B39/B5,0)
A40: Fixed, program & retention costs | B40: ='Monthly Plan'!$N$37 | E40: =IFERROR(B40/B5,0)
A41: Contingency | B41: ='Monthly Plan'!$N$40 | E41: =IFERROR(B41/B5,0)
A42: Total | B42: =SUM(B33:B41) | E42: =SUM(E33:E41)
A44: Input checks
A45: Seasonality sums to 100% | B45: =Inputs!$C$46
A46: Channel lead mix sums to 100% | B46: =Inputs!$C$57

Sheet Inputs
A1: 2027 Marketing Budget Model: Inputs
A2: Yellow cells with blue text are inputs. Change them and every other tab recalculates.
A4: Property profile
A5: Property name | B5: Harrison Landing | G5: From Property List (Haven Homes)
A6: Portfolio | B6: Haven Homes
A7: Location | B7: Simpsonville, SC (Greenville Co.) | G7: From Property List
A8: Property type / ownership | B8: Townhome / Owned-Managed
A9: Total units | B9: 166 | C9: units | G9: From Property List
A10: Average monthly rent | B10: 2100 | C10: $/mo | G10: PLACEHOLDER: replace with rent roll average
A11: Current occupancy | B11: 0.95 | C11: % | G11: PLACEHOLDER: current physical occupancy from PMS
A12: Target occupancy (end of 2027) | B12: 0.96 | C12: % | G12: PLACEHOLDER: owner/asset mgmt target
A13: Average days vacant per turn | B13: 30 | C13: days | G13: PLACEHOLDER: move-out to move-in, from PMS turn report
A15: Lease expirations & retention
A16: % of occupied leases expiring in 2027 | B16: 0.95 | C16: % | G16: PLACEHOLDER: count 2027 expirations in lease expiration report ÷ occupied units
A17: Renewal rate (of expiring leases) | B17: 0.55 | C17: % | G17: PLACEHOLDER: 2026 YTD renewals ÷ expirations
A18: Early terminations / skips (% of units per year) | B18: 0.03 | C18: % | G18: PLACEHOLDER: breaks, skips, evictions, transfers out
A19: Renewal incentive per renewal | B19: 100 | C19: $ | G19: PLACEHOLDER: gift card / upgrade offered to renew; enter 0 if none
A21: Leasing funnel (conversion rates)
A22: Lead → tour | B22: 0.25 | C22: % | G22: PLACEHOLDER: pull from CRM funnel report
A23: Tour → application | B23: 0.35 | C23: % | G23: PLACEHOLDER: includes self-guided tours
A24: Application → approval | B24: 0.7 | C24: % | G24: PLACEHOLDER: screening approval rate
A25: Approval → signed lease | B25: 0.9 | C25: % | G25: PLACEHOLDER: approved applicants who sign
A26: Lead-to-lease rate (calculated) | B26: =Inputs!$B$22*Inputs!$B$23*Inputs!$B$24*Inputs!$B$25 | G26: Industry range is often ~3–8%; your real number matters most
A28: Budget guardrails
A29: Contingency / reserve | B29: 0.1 | C29: % | G29: Cushion for slow months, price hikes, surprise vacancies
A30: Target max cost per lease (% of one month's rent) | B30: 0.5 | C30: % | G30: Common rule of thumb: keep acquisition cost under ~½ month's rent
A32: Lease expiration seasonality (% of 2027 expirations by month)
A33: Month | B33: % of expirations | G33: Notes
A34: Jan | B34: 0.05 | G34: PLACEHOLDER curve (summer-heavy). Replace with actual 2027 expiration counts by month.
A35: Feb | B35: 0.05
A36: Mar | B36: 0.07
A37: Apr | B37: 0.09
A38: May | B38: 0.11
A39: Jun | B39: 0.13
A40: Jul | B40: 0.13
A41: Aug | B41: 0.11
A42: Sep | B42: 0.08
A43: Oct | B43: 0.07
A44: Nov | B44: 0.06
A45: Dec | B45: 0.05
...

Sheet Monthly Plan
A1: ="2027 Monthly Lease Demand & Spend: "&Inputs!$B$5
A2: All cells are formulas driven by the Inputs tab. Assumes leads are generated in the same month as the lease need.
A4: Line item | B4: Jan | C4: Feb | D4: Mar | E4: Apr | F4: May | G4: Jun | H4: Jul | I4: Aug | J4: Sep | K4: Oct | L4: Nov | M4: Dec | N4: 2027 Total
A5: Lease demand
A6: Expiration seasonality | B6: =Inputs!$B$34 | C6: =Inputs!$B$35 | D6: =Inputs!$B$36 | E6: =Inputs!$B$37 | F6: =Inputs!$B$38 | G6: =Inputs!$B$39 | H6: =Inputs!$B$40 | I6: =Inputs!$B$41 | J6: =Inputs!$B$42 | K6: =Inputs!$B$43 | L6: =Inputs!$B$44 | M6: =Inputs!$B$45 | N6: =SUM(B6:M6)
A7: Leases expiring | B7: =(Inputs!$B$9*Inputs!$B$11*Inputs!$B$16)*B6 | C7: =(Inputs!$B$9*Inputs!$B$11*Inputs!$B$16)*C6 | D7: =(Inputs!$B$9*Inputs!$B$11*Inputs!$B$16)*D6 | E7: =(Inputs!$B$9*Inputs!$B$11*Inputs!$B$16)*E6 | F7: =(Inputs!$B$9*Inputs!$B$11*Inputs!$B$16)*F6 | G7: =(Inputs!$B$9*Inputs!$B$11*Inputs!$B$16)*G6 | H7: =(Inputs!$B$9*Inputs!$B$11*Inputs!$B$16)*H6 | I7: =(Inputs!$B$9*Inputs!$B$11*Inputs!$B$16)*I6 | ... M7: =(Inputs!$B$9*Inputs!$B$11*Inputs!$B$16)*M6 | N7: =SUM(B7:M7)
A8: Renewals | B8: =B7*Inputs!$B$17 | C8: =C7*Inputs!$B$17 | D8: =D7*Inputs!$B$17 | E8: =E7*Inputs!$B$17 | F8: =F7*Inputs!$B$17 | G8: =G7*Inputs!$B$17 | H8: =H7*Inputs!$B$17 | I8: =I7*Inputs!$B$17 | ... M8: =M7*Inputs!$B$17 | N8: =SUM(B8:M8)
A9: Move-outs at expiration | B9: =B7-B8 | C9: =C7-C8 | D9: =D7-D8 | E9: =E7-E8 | F9: =F7-F8 | G9: =G7-G8 | H9: =H7-H8 | I9: =I7-I8 | ... M9: =M7-M8 | N9: =SUM(B9:M9)
A10: Early terminations / skips | B10: =Inputs!$B$9*Inputs!$B$18/12 | C10: =Inputs!$B$9*Inputs!$B$18/12 | D10: =Inputs!$B$9*Inputs!$B$18/12 | E10: =Inputs!$B$9*Inputs!$B$18/12 | F10: =Inputs!$B$9*Inputs!$B$18/12 | G10: =Inputs!$B$9*Inputs!$B$18/12 | H10: =Inputs!$B$9*Inputs!$B$18/12 | I10: =Inputs!$B$9*Inputs!$B$18/12 | ... M10: =Inputs!$B$9*Inputs!$B$18/12 | N10: =SUM(B10:M10)
A11: Leases to reach target occupancy | B11: =MAX(0,Inputs!$B$9*(Inputs!$B$12-Inputs!$B$11))/12 | C11: =MAX(0,Inputs!$B$9*(Inputs!$B$12-Inputs!$B$11))/12 | D11: =MAX(0,Inputs!$B$9*(Inputs!$B$12-Inputs!$B$11))/12 | E11: =MAX(0,Inputs!$B$9*(Inputs!$B$12-Inputs!$B$11))/12 | F11: =MAX(0,Inputs!$B$9*(Inputs!$B$12-Inputs!$B$11))/12 | G11: =MAX(0,Inputs!$B$9*(Inputs!$B$12-Inputs!$B$11))/12 | H11: =MAX(0,Inputs!$B$9*(Inputs!$B$12-Inputs!$B$11))/12 | I11: =MAX(0,Inputs!$B$9*(Inputs!$B$12-Inputs!$B$11))/12 | ... M11: =MAX(0,Inputs!$B$9*(Inputs!$B$12-Inputs!$B$11))/12 | N11: =SUM(B11:M11)
A12: New leases needed | B12: =B9+B10+B11 | C12: =C9+C10+C11 | D12: =D9+D10+D11 | E12: =E9+E10+E11 | F12: =F9+F10+F11 | G12: =G9+G10+G11 | H12: =H9+H10+H11 | I12: =I9+I10+I11 | ... M12: =M9+M10+M11 | N12: =SUM(B12:M12)
A13: Funnel targets
A14: Leads needed | B14: =IFERROR(B12/Inputs!$B$26,0) | C14: =IFERROR(C12/Inputs!$B$26,0) | D14: =IFERROR(D12/Inputs!$B$26,0) | E14: =IFERROR(E12/Inputs!$B$26,0) | F14: =IFERROR(F12/Inputs!$B$26,0) | G14: =IFERROR(G12/Inputs!$B$26,0) | H14: =IFERROR(H12/Inputs!$B$26,0) | I14: =IFERROR(I12/Inputs!$B$26,0) | ... M14: =IFERROR(M12/Inputs!$B$26,0) | N14: =SUM(B14:M14)
A15: Tours needed | B15: =B14*Inputs!$B$22 | C15: =C14*Inputs!$B$22 | D15: =D14*Inputs!$B$22 | E15: =E14*Inputs!$B$22 | F15: =F14*Inputs!$B$22 | G15: =G14*Inputs!$B$22 | H15: =H14*Inputs!$B$22 | I15: =I14*Inputs!$B$22 | ... M15: =M14*Inputs!$B$22 | N15: =SUM(B15:M15)
A16: Applications needed | B16: =B15*Inputs!$B$23 | C16: =C15*Inputs!$B$23 | D16: =D15*Inputs!$B$23 | E16: =E15*Inputs!$B$23 | F16: =F15*Inputs!$B$23 | G16: =G15*Inputs!$B$23 | H16: =H15*Inputs!$B$23 | I16: =I15*Inputs!$B$23 | ... M16: =M15*Inputs!$B$23 | N16: =SUM(B16:M16)
A17: Spend by lead channel ($)
A18: =Inputs!$A$50 | B18: =Inputs!$D$50+B14*Inputs!$B$50*Inputs!$C$50+B12*Inputs!$B$50*Inputs!$E$50 | C18: =Inputs!$D$50+C14*Inputs!$B$50*Inputs!$C$50+C12*Inputs!$B$50*Inputs!$E$50 | D18: =Inputs!$D$50+D14*Inputs!$B$50*Inputs!$C$50+D12*Inputs!$B$50*Inputs!$E$50 | E18: =Inputs!$D$50+E14*Inputs!$B$50*Inputs!$C$50+E12*Inputs!$B$50*Inputs!$E$50 | F18: =Inputs!$D$50+F14*Inputs!$B$50*Inputs!$C$50+F12*Inputs!$B$50*Inputs!$E$50 | G18: =Inputs!$D$50+G14*Inputs!$B$50*Inputs!$C$50+G12*Inputs!$B$50*Inputs!$E$50 | H18: =Inputs!$D$50+H14*Inputs!$B$50*Inputs!$C$50+H12*Inputs!$B$50*Inputs!$E$50 | I18: =Inputs!$D$50+I14*Inputs!$B$50*Inputs!$C$50+I12*Inputs!$B$50*Inputs!$E$50 | ... M18: =Inputs!$D$50+M14*Inputs!$B$50*Inputs!$C$50+M12*Inputs!$B$50*Inputs!$E$50 | N18: =SUM(B18:M18)
A19: =Inputs!$A$51 | B19: =Inputs!$D$51+B14*Inputs!$B$51*Inputs!$C$51+B12*Inputs!$B$51*Inputs!$E$51 | C19: =Inputs!$D$51+C14*Inputs!$B$51*Inputs!$C$51+C12*Inputs!$B$51*Inputs!$E$51 | D19: =Inputs!$D$51+D14*Inputs!$B$51*Inputs!$C$51+D12*Inputs!$B$51*Inputs!$E$51 | E19: =Inputs!$D$51+E14*Inputs!$B$51*Inputs!$C$51+E12*Inputs!$B$51*Inputs!$E$51 | F19: =Inputs!$D$51+F14*Inputs!$B$51*Inputs!$C$51+F12*Inputs!$B$51*Inputs!$E$51 | G19: =Inputs!$D$51+G14*Inputs!$B$51*Inputs!$C$51+G12*Inputs!$B$51*Inputs!$E$51 | H19: =Inputs!$D$51+H14*Inputs!$B$51*Inputs!$C$51+H12*Inputs!$B$51*Inputs!$E$51 | I19: =Inputs!$D$51+I14*Inputs!$B$51*Inputs!$C$51+I12*Inputs!$B$51*Inputs!$E$51 | ... M19: =Inputs!$D$51+M14*Inputs!$B$51*Inputs!$C$51+M12*Inputs!$B$51*Inputs!$E$51 | N19: =SUM(B19:M19)
A20: =Inputs!$A$52 | B20: =Inputs!$D$52+B14*Inputs!$B$52*Inputs!$C$52+B12*Inputs!$B$52*Inputs!$E$52 | C20: =Inputs!$D$52+C14*Inputs!$B$52*Inputs!$C$52+C12*Inputs!$B$52*Inputs!$E$52 | D20: =Inputs!$D$52+D14*Inputs!$B$52*Inputs!$C$52+D12*Inputs!$B$52*Inputs!$E$52 | E20: =Inputs!$D$52+E14*Inputs!$B$52*Inputs!$C$52+E12*Inputs!$B$52*Inputs!$E$52 | F20: =Inputs!$D$52+F14*Inputs!$B$52*Inputs!$C$52+F12*Inputs!$B$52*Inputs!$E$52 | G20: =Inputs!$D$52+G14*Inputs!$B$52*Inputs!$C$52+G12*Inputs!$B$52*Inputs!$E$52 | H20: =Inputs!$D$52+H14*Inputs!$B$52*Inputs!$C$52+H12*Inputs!$B$52*Inputs!$E$52 | I20: =Inputs!$D$52+I14*Inputs!$B$52*Inputs!$C$52+I12*Inputs!$B$52*Inputs!$E$52 | ... M20: =Inputs!$D$52+M14*Inputs!$B$52*Inputs!$C$52+M12*Inputs!$B$52*Inputs!$E$52 | N20: =SUM(B20:M20)
A21: =Inputs!$A$53 | B21: =Inputs!$D$53+B14*Inputs!$B$53*Inputs!$C$53+B12*Inputs!$B$53*Inputs!$E$53 | C21: =Inputs!$D$53+C14*Inputs!$B$53*Inputs!$C$53+C12*Inputs!$B$53*Inputs!$E$53 | D21: =Inputs!$D$53+D14*Inputs!$B$53*Inputs!$C$53+D12*Inputs!$B$53*Inputs!$E$53 | E21: =Inputs!$D$53+E14*Inputs!$B$53*Inputs!$C$53+E12*Inputs!$B$53*Inputs!$E$53 | F21: =Inputs!$D$53+F14*Inputs!$B$53*Inputs!$C$53+F12*Inputs!$B$53*Inputs!$E$53 | G21: =Inputs!$D$53+G14*Inputs!$B$53*Inputs!$C$53+G12*Inputs!$B$53*Inputs!$E$53 | H21: =Inputs!$D$53+H14*Inputs!$B$53*Inputs!$C$53+H12*Inputs!$B$53*Inputs!$E$53 | I21: =Inputs!$D$53+I14*Inputs!$B$53*Inputs!$C$53+I12*Inputs!$B$53*Inputs!$E$53 | ... M21: =Inputs!$D$53+M14*Inputs!$B$53*Inputs!$C$53+M12*Inputs!$B$53*Inputs!$E$53 | N21: =SUM(B21:M21)
A22: =Inputs!$A$54 | B22: =Inputs!$D$54+B14*Inputs!$B$54*Inputs!$C$54+B12*Inputs!$B$54*Inputs!$E$54 | C22: =Inputs!$D$54+C14*Inputs!$B$54*Inputs!$C$54+C12*Inputs!$B$54*Inputs!$E$54 | D22: =Inputs!$D$54+D14*Inputs!$B$54*Inputs!$C$54+D12*Inputs!$B$54*Inputs!$E$54 | E22: =Inputs!$D$54+E14*Inputs!$B$54*Inputs!$C$54+E12*Inputs!$B$54*Inputs!$E$54 | F22: =Inputs!$D$54+F14*Inputs!$B$54*Inputs!$C$54+F12*Inputs!$B$54*Inputs!$E$54 | G22: =Inputs!$D$54+G14*Inputs!$B$54*Inputs!$C$54+G12*Inputs!$B$54*Inputs!$E$54 | H22: =Inputs!$D$54+H14*Inputs!$B$54*Inputs!$C$54+H12*Inputs!$B$54*Inputs!$E$54 | I22: =Inputs!$D$54+I14*Inputs!$B$54*Inputs!$C$54+I12*Inputs!$B$54*Inputs!$E$54 | ... M22: =Inputs!$D$54+M14*Inputs!$B$54*Inputs!$C$54+M12*Inputs!$B$54*Inputs!$E$54 | N22: =SUM(B22:M22)
A23: =Inputs!$A$55 | B23: =Inputs!$D$55+B14*Inputs!$B$55*Inputs!$C$55+B12*Inputs!$B$55*Inputs!$E$55 | C23: =Inputs!$D$55+C14*Inputs!$B$55*Inputs!$C$55+C12*Inputs!$B$55*Inputs!$E$55 | D23: =Inputs!$D$55+D14*Inputs!$B$55*Inputs!$C$55+D12*Inputs!$B$55*Inputs!$E$55 | E23: =Inputs!$D$55+E14*Inputs!$B$55*Inputs!$C$55+E12*Inputs!$B$55*Inputs!$E$55 | F23: =Inputs!$D$55+F14*Inputs!$B$55*Inputs!$C$55+F12*Inputs!$B$55*Inputs!$E$55 | G23: =Inputs!$D$55+G14*Inputs!$B$55*Inputs!$C$55+G12*Inputs!$B$55*Inputs!$E$55 | H23: =Inputs!$D$55+H14*Inputs!$B$55*Inputs!$C$55+H12*Inputs!$B$55*Inputs!$E$55 | I23: =Inputs!$D$55+I14*Inputs!$B$55*Inputs!$C$55+I12*Inputs!$B$55*Inputs!$E$55 | ... M23: =Inputs!$D$55+M14*Inputs!$B$55*Inputs!$C$55+M12*Inputs!$B$55*Inputs!$E$55 | N23: =SUM(B23:M23)
A24: =Inputs!$A$56 | B24: =Inputs!$D$56+B14*Inputs!$B$56*Inputs!$C$56+B12*Inputs!$B$56*Inputs!$E$56 | C24: =Inputs!$D$56+C14*Inputs!$B$56*Inputs!$C$56+C12*Inputs!$B$56*Inputs!$E$56 | D24: =Inputs!$D$56+D14*Inputs!$B$56*Inputs!$C$56+D12*Inputs!$B$56*Inputs!$E$56 | E24: =Inputs!$D$56+E14*Inputs!$B$56*Inputs!$C$56+E12*Inputs!$B$56*Inputs!$E$56 | F24: =Inputs!$D$56+F14*Inputs!$B$56*Inputs!$C$56+F12*Inputs!$B$56*Inputs!$E$56 | G24: =Inputs!$D$56+G14*Inputs!$B$56*Inputs!$C$56+G12*Inputs!$B$56*Inputs!$E$56 | H24: =Inputs!$D$56+H14*Inputs!$B$56*Inputs!$C$56+H12*Inputs!$B$56*Inputs!$E$56 | I24: =Inputs!$D$56+I14*Inputs!$B$56*Inputs!$C$56+I12*Inputs!$B$56*Inputs!$E$56 | ... M24: =Inputs!$D$56+M14*Inputs!$B$56*Inputs!$C$56+M12*Inputs!$B$56*Inputs!$E$56 | N24: =SUM(B24:M24)
A25: Channel subtotal | B25: =SUM(B18:B24) | C25: =SUM(C18:C24) | D25: =SUM(D18:D24) | E25: =SUM(E18:E24) | F25: =SUM(F18:F24) | G25: =SUM(G18:G24) | H25: =SUM(H18:H24) | I25: =SUM(I18:I24) | ... M25: =SUM(M18:M24) | N25: =SUM(B25:M25)
A26: Fixed, program & retention costs ($)
A27: =Inputs!$A$62 | B27: =Inputs!$B$62+Inputs!$C$62/12 | C27: =Inputs!$B$62+Inputs!$C$62/12 | D27: =Inputs!$B$62+Inputs!$C$62/12 | E27: =Inputs!$B$62+Inputs!$C$62/12 | F27: =Inputs!$B$62+Inputs!$C$62/12 | G27: =Inputs!$B$62+Inputs!$C$62/12 | H27: =Inputs!$B$62+Inputs!$C$62/12 | I27: =Inputs!$B$62+Inputs!$C$62/12 | ... M27: =Inputs!$B$62+Inputs!$C$62/12 | N27: =SUM(B27:M27)
A28: =Inputs!$A$63 | B28: =Inputs!$B$63+Inputs!$C$63/12 | C28: =Inputs!$B$63+Inputs!$C$63/12 | D28: =Inputs!$B$63+Inputs!$C$63/12 | E28: =Inputs!$B$63+Inputs!$C$63/12 | F28: =Inputs!$B$63+Inputs!$C$63/12 | G28: =Inputs!$B$63+Inputs!$C$63/12 | H28: =Inputs!$B$63+Inputs!$C$63/12 | I28: =Inputs!$B$63+Inputs!$C$63/12 | ... M28: =Inputs!$B$63+Inputs!$C$63/12 | N28: =SUM(B28:M28)
A29: =Inputs!$A$64 | B29: =Inputs!$B$64+Inputs!$C$64/12 | C29: =Inputs!$B$64+Inputs!$C$64/12 | D29: =Inputs!$B$64+Inputs!$C$64/12 | E29: =Inputs!$B$64+Inputs!$C$64/12 | F29: =Inputs!$B$64+Inputs!$C$64/12 | G29: =Inputs!$B$64+Inputs!$C$64/12 | H29: =Inputs!$B$64+Inputs!$C$64/12 | I29: =Inputs!$B$64+Inputs!$C$64/12 | ... M29: =Inputs!$B$64+Inputs!$C$64/12 | N29: =SUM(B29:M29)
A30: =Inputs!$A$65 | B30: =Inputs!$B$65+Inputs!$C$65/12 | C30: =Inputs!$B$65+Inputs!$C$65/12 | D30: =Inputs!$B$65+Inputs!$C$65/12 | E30: =Inputs!$B$65+Inputs!$C$65/12 | F30: =Inputs!$B$65+Inputs!$C$65/12 | G30: =Inputs!$B$65+Inputs!$C$65/12 | H30: =Inputs!$B$65+Inputs!$C$65/12 | I30: =Inputs!$B$65+Inputs!$C$65/12 | ... M30: =Inputs!$B$65+Inputs!$C$65/12 | N30: =SUM(B30:M30)
A31: =Inputs!$A$66 | B31: =Inputs!$B$66+Inputs!$C$66/12 | C31: =Inputs!$B$66+Inputs!$C$66/12 | D31: =Inputs!$B$66+Inputs!$C$66/12 | E31: =Inputs!$B$66+Inputs!$C$66/12 | F31: =Inputs!$B$66+Inputs!$C$66/12 | G31: =Inputs!$B$66+Inputs!$C$66/12 | H31: =Inputs!$B$66+Inputs!$C$66/12 | I31: =Inputs!$B$66+Inputs!$C$66/12 | ... M31: =Inputs!$B$66+Inputs!$C$66/12 | N31: =SUM(B31:M31)
A32: =Inputs!$A$67 | B32: =Inputs!$B$67+Inputs!$C$67/12 | C32: =Inputs!$B$67+Inputs!$C$67/12 | D32: =Inputs!$B$67+Inputs!$C$67/12 | E32: =Inputs!$B$67+Inputs!$C$67/12 | F32: =Inputs!$B$67+Inputs!$C$67/12 | G32: =Inputs!$B$67+Inputs!$C$67/12 | H32: =Inputs!$B$67+Inputs!$C$67/12 | I32: =Inputs!$B$67+Inputs!$C$67/12 | ... M32: =Inputs!$B$67+Inputs!$C$67/12 | N32: =SUM(B32:M32)
A33: =Inputs!$A$68 | B33: =Inputs!$B$68+Inputs!$C$68/12 | C33: =Inputs!$B$68+Inputs!$C$68/12 | D33: =Inputs!$B$68+Inputs!$C$68/12 | E33: =Inputs!$B$68+Inputs!$C$68/12 | F33: =Inputs!$B$68+Inputs!$C$68/12 | G33: =Inputs!$B$68+Inputs!$C$68/12 | H33: =Inputs!$B$68+Inputs!$C$68/12 | I33: =Inputs!$B$68+Inputs!$C$68/12 | ... M33: =Inputs!$B$68+Inputs!$C$68/12 | N33: =SUM(B33:M33)
A34: =Inputs!$A$69 | B34: =Inputs!$B$69+Inputs!$C$69/12 | C34: =Inputs!$B$69+Inputs!$C$69/12 | D34: =Inputs!$B$69+Inputs!$C$69/12 | E34: =Inputs!$B$69+Inputs!$C$69/12 | F34: =Inputs!$B$69+Inputs!$C$69/12 | G34: =Inputs!$B$69+Inputs!$C$69/12 | H34: =Inputs!$B$69+Inputs!$C$69/12 | I34: =Inputs!$B$69+Inputs!$C$69/12 | ... M34: =Inputs!$B$69+Inputs!$C$69/12 | N34: =SUM(B34:M34)
A35: =Inputs!$A$70 | B35: =Inputs!$B$70+Inputs!$C$70/12 | C35: =Inputs!$B$70+Inputs!$C$70/12 | D35: =Inputs!$B$70+Inputs!$C$70/12 | E35: =Inputs!$B$70+Inputs!$C$70/12 | F35: =Inputs!$B$70+Inputs!$C$70/12 | G35: =Inputs!$B$70+Inputs!$C$70/12 | H35: =Inputs!$B$70+Inputs!$C$70/12 | I35: =Inputs!$B$70+Inputs!$C$70/12 | ... M35: =Inputs!$B$70+Inputs!$C$70/12 | N35: =SUM(B35:M35)
A36: Renewal incentives | B36: =B8*Inputs!$B$19 | C36: =C8*Inputs!$B$19 | D36: =D8*Inputs!$B$19 | E36: =E8*Inputs!$B$19 | F36: =F8*Inputs!$B$19 | G36: =G8*Inputs!$B$19 | H36: =H8*Inputs!$B$19 | I36: =I8*Inputs!$B$19 | ... M36: =M8*Inputs!$B$19 | N36: =SUM(B36:M36)
A37: Fixed & retention subtotal | B37: =SUM(B27:B36) | C37: =SUM(C27:C36) | D37: =SUM(D27:D36) | E37: =SUM(E27:E36) | F37: =SUM(F27:F36) | G37: =SUM(G27:G36) | H37: =SUM(H27:H36) | I37: =SUM(I27:I36) | ... M37: =SUM(M27:M36) | N37: =SUM(B37:M37)
A38: Total
A39: Budget before contingency | B39: =B25+B37 | C39: =C25+C37 | D39: =D25+D37 | E39: =E25+E37 | F39: =F25+F37 | G39: =G25+G37 | H39: =H25+H37 | I39: =I25+I37 | ... M39: =M25+M37 | N39: =SUM(B39:M39)
A40: Contingency | B40: =B39*Inputs!$B$29 | C40: =C39*Inputs!$B$29 | D40: =D39*Inputs!$B$29 | E40: =E39*Inputs!$B$29 | F40: =F39*Inputs!$B$29 | G40: =G39*Inputs!$B$29 | H40: =H39*Inputs!$B$29 | I40: =I39*Inputs!$B$29 | ... M40: =M39*Inputs!$B$29 | N40: =SUM(B40:M40)
A41: TOTAL MARKETING BUDGET | B41: =B39+B40 | C41: =C39+C40 | D41: =D39+D40 | E41: =E39+E40 | F41: =F39+F40 | G41: =G39+G40 | H41: =H39+H40 | I41: =I39+I40 | ... M41: =M39+M40 | N41: =SUM(B41:M41)

Sheet Read Me
A1: How this model works
A2: Lease demand drives the budget: Units × occupancy × % expiring → renewals vs. move-outs → new leases needed → ÷ lead-to-lease rate → leads needed → × cost per lead by channel → + fixed costs → + contingency.
A4: Tabs
A5: Budget Summary: headline budget, $/unit, cost per lease, vacancy-cost justification, line items vs. 2026.
A6: Inputs: the ONLY tab you edit. Property facts, retention, funnel, seasonality, channels, fixed costs.
A7: Monthly Plan: month-by-month leases, leads and spend, so you can see the summer peak and pace spend.
A9: Color legend
A10: Blue text on yellow = input you can change · Black = formula · Green = pulled from another tab.
A12: Status of the numbers
A13: Units, name, location and type come from the Haven Homes property list. Everything marked PLACEHOLDER is an industry-style starting value; replace with Harrison Landing actuals.
A15: Data to pull for Harrison Landing (replace placeholders)
A16: 1. Rent roll: average rent and current occupancy (PMS).
... A24: Copy this workbook once per property (or duplicate the Inputs tab) and change the Inputs. Prosper 207 is in lease-up and needs a separate lease-up model (absorption pace, not turnover).
